Workbook

Sheet Summary
B2: Testing to scaling creative report (new content added to testing since 1 Jan 2026)
B4: Data through
B5: As-of date | C5: 46320
B6: Report window start | C6: 46023
B7: Min spend in winning campaigns to count as scaled (INR) | C7: 5000
B8: Recent launch cut off (days) for the matured view | C8: 14
B10: Headline metrics
B11: New content pieces added to testing | C11: =COUNTA(Creatives!$A$2:$A$264) -> 263
B12: Moved to scaling | C12: =COUNTIF(Creatives!$Q$2:$Q$264,"Yes") -> 59
B13: Scale rate (moved to scaling / added) | C13: =IFERROR(C12/C11,0) -> 0.2243346
B14: Added at least 14 days ago (matured cohort) | C14: =COUNTIF(Creatives!$G$2:$G$264,">="&C8) -> 237
B15: Of those, moved to scaling | C15: =COUNTIFS(Creatives!$G$2:$G$264,">="&C8,Creatives!$Q$2:$Q$264,"Yes") -> 58
B16: Scale rate, matured cohort | C16: =IFERROR(C15/C14,0) -> 0.24472574
B17: Avg days from testing launch to scaling | C17: =IFERROR(AVERAGEIF(Creatives!$Q$2:$Q$264,"Yes",Creatives!$S$2:$S$264),0) -> 13.20339
B18: Total testing spend (INR) | C18: =SUM(Creatives!$H$2:$H$264) -> 2097022.3
B19: Testing spend per new piece (INR) | C19: =IFERROR(C18/C11,0) -> 7973.4687
B20: Testing spend on pieces that scaled (INR) | C20: =SUMIF(Creatives!$Q$2:$Q$264,"Yes",Creatives!$H$2:$H$264) -> 600902.79
B21: Total spend in scaling campaigns on those pieces (INR) | C21: =SUM(Creatives!$U$2:$U$264) -> 7316800.8
B22: Cost per appointment in testing, scaled pieces (INR) | C22: =IFERROR(SUMIF(Creatives!$Q$2:$Q$264,"Yes",Creatives!$H$2:$H$264)/SUMIF(Creatives!$Q$2:$Q$264,"Yes",Creatives!$O$2:$O$264),0) -> 3414.2204
B23: Cost per appointment in testing, not scaled pieces (INR) | C23: =IFERROR(SUMIF(Creatives!$Q$2:$Q$264,"No",Creatives!$H$2:$H$264)/SUMIF(Creatives!$Q$2:$Q$264,"No",Creatives!$O$2:$O$264),0) -> 4479.3996
B24: Testing CTR, scaled pieces | C24: =IFERROR(SUMIF(Creatives!$Q$2:$Q$264,"Yes",Creatives!$J$2:$J$264)/SUMIF(Creatives!$Q$2:$Q$264,"Yes",Creatives!$I$2:$I$264),0) -> 0.025282413
B25: Testing CTR, not scaled pieces | C25: =IFERROR(SUMIF(Creatives!$Q$2:$Q$264,"No",Creatives!$J$2:$J$264)/SUMIF(Creatives!$Q$2:$Q$264,"No",Creatives!$I$2:$I$264),0) -> 0.00093054216
B26: Testing hook rate, scaled pieces | C26: =IFERROR(SUMIF(Creatives!$Q$2:$Q$264,"Yes",Creatives!$K$2:$K$264)/SUMIF(Creatives!$Q$2:$Q$264,"Yes",Creatives!$I$2:$I$264),0) -> 0.22942287
B27: Testing hook rate, not scaled pieces | C27: =IFERROR(SUMIF(Creatives!$Q$2:$Q$264,"No",Creatives!$K$2:$K$264)/SUMIF(Creatives!$Q$2:$Q$264,"No",Creatives!$I$2:$I$264),0) -> 0.064594849
B28: Testing CPM, scaled pieces (INR) | C28: =IFERROR(SUMIF(Creatives!$Q$2:$Q$264,"Yes",Creatives!$H$2:$H$264)/SUMIF(Creatives!$Q$2:$Q$264,"Yes",Creatives!$I$2:$I$264)*1000,0) -> 68.006932
B29: Testing CPM, not scaled pieces (INR) | C29: =IFERROR(SUMIF(Creatives!$Q$2:$Q$264,"No",Creatives!$H$2:$H$264)/SUMIF(Creatives!$Q$2:$Q$264,"No",Creatives!$I$2:$I$264)*1000,0) -> 23.616662
B31: By launch month (cohort view)
B32: Launch month | C32: New pieces added | D32: Moved to scaling | E32: Scale rate | F32: Avg days to scale | G32: Testing spend (INR) | H32: Testing spend per piece (INR) | I32: Testing CTR | J32: Testing hook rate | K32: Testing CPM (INR) | L32: Testing appointments | M32: Cost per appointment (INR) | N32: Scaling spend on these pieces (INR)
B33: 2026-01 | C33: =COUNTIF(Creatives!$C$2:$C$264,B33) -> 0 | D33: =COUNTIFS(Creatives!$C$2:$C$264,B33,Creatives!$Q$2:$Q$264,"Yes") -> 0 | E33: =IFERROR(D33/C33,0) -> 0 | F33: =IFERROR(AVERAGEIFS(Creatives!$S$2:$S$264,Creatives!$C$2:$C$264,B33,Creatives!$Q$2:$Q$264,"Yes"),0) -> 0 | G33: =SUMIF(Creatives!$C$2:$C$264,B33,Creatives!$H$2:$H$264) -> 0 | H33: =IFERROR(G33/C33,0) -> 0 | I33: =IFERROR(SUMIF(Creatives!$C$2:$C$264,B33,Creatives!$J$2:$J$264)/SUMIF(Creatives!$C$2:$C$264,B33,Creatives!$I$2:$I$264),0) -> 0 | J33: =IFERROR(SUMIF(Creatives!$C$2:$C$264,B33,Creatives!$K$2:$K$264)/SUMIF(Creatives!$C$2:$C$264,B33,Creatives!$I$2:$I$264),0) -> 0 | K33: =IFERROR(G33/SUMIF(Creatives!$C$2:$C$264,B33,Creatives!$I$2:$I$264)*1000,0) -> 0 | L33: =SUMIF(Creatives!$C$2:$C$264,B33,Creatives!$O$2:$O$264) -> 0 | M33: =IFERROR(G33/L33,0) -> 0 | N33: =SUMIF(Creatives!$C$2:$C$264,B33,Creatives!$U$2:$U$264) -> 0
B34: 2026-02 | C34: =COUNTIF(Creatives!$C$2:$C$264,B34) -> 8 | D34: =COUNTIFS(Creatives!$C$2:$C$264,B34,Creatives!$Q$2:$Q$264,"Yes") -> 0 | E34: =IFERROR(D34/C34,0) -> 0 | F34: =IFERROR(AVERAGEIFS(Creatives!$S$2:$S$264,Creatives!$C$2:$C$264,B34,Creatives!$Q$2:$Q$264,"Yes"),0) -> 0 | G34: =SUMIF(Creatives!$C$2:$C$264,B34,Creatives!$H$2:$H$264) -> 191071.19 | H34: =IFERROR(G34/C34,0) -> 23883.899 | I34: =IFERROR(SUMIF(Creatives!$C$2:$C$264,B34,Creatives!$J$2:$J$264)/SUMIF(Creatives!$C$2:$C$264,B34,Creatives!$I$2:$I$264),0) -> 0.0046684652 | J34: =IFERROR(SUMIF(Creatives!$C$2:$C$264,B34,Creatives!$K$2:$K$264)/SUMIF(Creatives!$C$2:$C$264,B34,Creatives!$I$2:$I$264),0) -> 0.12801702 | K34: =IFERROR(G34/SUMIF(Creatives!$C$2:$C$264,B34,Creatives!$I$2:$I$264)*1000,0) -> 136.76927 | L34: =SUMIF(Creatives!$C$2:$C$264,B34,Creatives!$O$2:$O$264) -> 33 | M34: =IFERROR(G34/L34,0) -> 5790.0361 | N34: =SUMIF(Creatives!$C$2:$C$264,B34,Creatives!$U$2:$U$264) -> 0
B35: 2026-03 | C35: =COUNTIF(Creatives!$C$2:$C$264,B35) -> 19 | D35: =COUNTIFS(Creatives!$C$2:$C$264,B35,Creatives!$Q$2:$Q$264,"Yes") -> 10 | E35: =IFERROR(D35/C35,0) -> 0.52631579 | F35: =IFERROR(AVERAGEIFS(Creatives!$S$2:$S$264,Creatives!$C$2:$C$264,B35,Creatives!$Q$2:$Q$264,"Yes"),0) -> 12.4 | G35: =SUMIF(Creatives!$C$2:$C$264,B35,Creatives!$H$2:$H$264) -> 240171.86 | H35: =IFERROR(G35/C35,0) -> 12640.624 | I35: =IFERROR(SUMIF(Creatives!$C$2:$C$264,B35,Creatives!$J$2:$J$264)/SUMIF(Creatives!$C$2:$C$264,B35,Creatives!$I$2:$I$264),0) -> 0.027687393 | J35: =IFERROR(SUMIF(Creatives!$C$2:$C$264,B35,Creatives!$K$2:$K$264)/SUMIF(Creatives!$C$2:$C$264,B35,Creatives!$I$2:$I$264),0) -> 0.22981556 | K35: =IFERROR(G35/SUMIF(Creatives!$C$2:$C$264,B35,Creatives!$I$2:$I$264)*1000,0) -> 30.816759 | L35: =SUMIF(Creatives!$C$2:$C$264,B35,Creatives!$O$2:$O$264) -> 45 | M35: =IFERROR(G35/L35,0) -> 5337.1524 | N35: =SUMIF(Creatives!$C$2:$C$264,B35,Creatives!$U$2:$U$264) -> 2286157.6
B36: 2026-04 | C36: =COUNTIF(Creatives!$C$2:$C$264,B36) -> 28 | D36: =COUNTIFS(Creatives!$C$2:$C$264,B36,Creatives!$Q$2:$Q$264,"Yes") -> 9 | E36: =IFERROR(D36/C36,0) -> 0.32142857 | F36: =IFERROR(AVERAGEIFS(Creatives!$S$2:$S$264,Creatives!$C$2:$C$264,B36,Creatives!$Q$2:$Q$264,"Yes"),0) -> 29.333333 | G36: =SUMIF(Creatives!$C$2:$C$264,B36,Creatives!$H$2:$H$264) -> 163533.03 | H36: =IFERROR(G36/C36,0) -> 5840.4654 | I36: =IFERROR(SUMIF(Creatives!$C$2:$C$264,B36,Creatives!$J$2:$J$264)/SUMIF(Creatives!$C$2:$C$264,B36,Creatives!$I$2:$I$264),0) -> 0.0062469045 | J36: =IFERROR(SUMIF(Creatives!$C$2:$C$264,B36,Creatives!$K$2:$K$264)/SUMIF(Creatives!$C$2:$C$264,B36,Creatives!$I$2:$I$264),0) -> 0.19391285 | K36: =IFERROR(G36/SUMIF(Creatives!$C$2:$C$264,B36,Creatives!$I$2:$I$264)*1000,0) -> 304.49336 | L36: =SUMIF(Creatives!$C$2:$C$264,B36,Creatives!$O$2:$O$264) -> 39 | M36: =IFERROR(G36/L36,0) -> 4193.1546 | N36: =SUMIF(Creatives!$C$2:$C$264,B36,Creatives!$U$2:$U$264) -> 702229.68
B37: 2026-05 | C37: =COUNTIF(Creatives!$C$2:$C$264,B37) -> 52 | D37: =COUNTIFS(Creatives!$C$2:$C$264,B37,Creatives!$Q$2:$Q$264,"Yes") -> 7 | E37: =IFERROR(D37/C37,0) -> 0.13461538 | F37: =IFERROR(AVERAGEIFS(Creatives!$S$2:$S$264,Creatives!$C$2:$C$264,B37,Creatives!$Q$2:$Q$264,"Yes"),0) -> 6 | G37: =SUMIF(Creatives!$C$2:$C$264,B37,Creatives!$H$2:$H$264) -> 557075.66 | H37: =IFERROR(G37/C37,0) -> 10712.993 | I37: =IFERROR(SUMIF(Creatives!$C$2:$C$264,B37,Creatives!$J$2:$J$264)/SUMIF(Creatives!$C$2:$C$264,B37,Creatives!$I$2:$I$264),0) -> 0.00061461617 | J37: =IFERROR(SUMIF(Creatives!$C$2:$C$264,B37,Creatives!$K$2:$K$264)/SUMIF(Creatives!$C$2:$C$264,B37,Creatives!$I$2:$I$264),0) -> 0.058410249 | K37: =IFERROR(G37/SUMIF(Creatives!$C$2:$C$264,B37,Creatives!$I$2:$I$264)*1000,0) -> 9.2966876 | L37: =SUMIF(Creatives!$C$2:$C$264,B37,Creatives!$O$2:$O$264) -> 85 | M37: =IFERROR(G37/L37,0) -> 6553.8313 | N37: =SUMIF(Creatives!$C$2:$C$264,B37,Creatives!$U$2:$U$264) -> 606307.36
B38: 2026-06 | C38: =COUNTIF(Creatives!$C$2:$C$264,B38) -> 35 | D38: =COUNTIFS(Creatives!$C$2:$C$264,B38,Creatives!$Q$2:$Q$264,"Yes") -> 10 | E38: =IFERROR(D38/C38,0) -> 0.28571429 | F38: =IFERROR(AVERAGEIFS(Creatives!$S$2:$S$264,Creatives!$C$2:$C$264,B38,Creatives!$Q$2:$Q$264,"Yes"),0) -> 10.6 | G38: =SUMIF(Creatives!$C$2:$C$264,B38,Creatives!$H$2:$H$264) -> 359093.82 | H38: =IFERROR(G38/C38,0) -> 10259.823 | I38: =IFERROR(SUMIF(Creatives!$C$2:$C$264,B38,Creatives!$J$2:$J$264)/SUMIF(Creatives!$C$2:$C$264,B38,Creatives!$I$2:$I$264),0) -> 0.0065149436 | J38: =IFERROR(SUMIF(Creatives!$C$2:$C$264,B38,Creatives!$K$2:$K$264)/SUMIF(Creatives!$C$2:$C$264,B38,Creatives!$I$2:$I$264),0) -> 0.19195454 | K38: =IFERROR(G38/SUMIF(Creatives!$C$2:$C$264,B38,Creatives!$I$2:$I$264)*1000,0) -> 273.84713 | L38: =SUMIF(Creatives!$C$2:$C$264,B38,Creatives!$O$2:$O$264) -> 108 | M38: =IFERROR(G38/L38,0) -> 3324.9428 | N38: =SUMIF(Creatives!$C$2:$C$264,B38,Creatives!$U$2:$U$264) -> 1329009.5
B39: 2026-07 | C39: =COUNTIF(Creatives!$C$2:$C$264,B39) -> 24 | D39: =COUNTIFS(Creatives!$C$2:$C$264,B39,Creatives!$Q$2:$Q$264,"Yes") -> 8 | E39: =IFERROR(D39/C39,0) -> 0.33333333 | F39: =IFERROR(AVERAGEIFS(Creatives!$S$2:$S$264,Creatives!$C$2:$C$264,B39,Creatives!$Q$2:$Q$264,"Yes"),0) -> 15.5 | G39: =SUMIF(Creatives!$C$2:$C$264,B39,Creatives!$H$2:$H$264) -> 124789.85 | H39: =IFERROR(G39/C39,0) -> 5199.5771 | I39: =IFERROR(SUMIF(Creatives!$C$2:$C$264,B39,Creatives!$J$2:$J$264)/SUMIF(Creatives!$C$2:$C$264,B39,Creatives!$I$2:$I$264),0) -> 0.0096731466 | J39: =IFERROR(SUMIF(Creatives!$C$2:$C$264,B39,Creatives!$K$2:$K$264)/SUMIF(Creatives!$C$2:$C$264,B39,Creatives!$I$2:$I$264),0) -> 0.28145357 | K39: =IFERROR(G39/SUMIF(Creatives!$C$2:$C$264,B39,Creatives!$I$2:$I$264)*1000,0) -> 376.51607 | L39: =SUMIF(Creatives!$C$2:$C$264,B39,Creatives!$O$2:$O$264) -> 45 | M39: =IFERROR(G39/L39,0) -> 2773.1078 | N39: =SUMIF(Creatives!$C$2:$C$264,B39,Creatives!$U$2:$U$264) -> 941152.49
B40: 2026-08 | C40: =COUNTIF(Creatives!$C$2:$C$264,B40) -> 31 | D40: =COUNTIFS(Creatives!$C$2:$C$264,B40,Creatives!$Q$2:$Q$264,"Yes") -> 6 | E40: =IFERROR(D40/C40,0) -> 0.19354839 | F40: =IFERROR(AVERAGEIFS(Creatives!$S$2:$S$264,Creatives!$C$2:$C$264,B40,Creatives!$Q$2:$Q$264,"Yes"),0) -> 6.6666667 | G40: =SUMIF(Creatives!$C$2:$C$264,B40,Creatives!$H$2:$H$264) -> 132839.82 | H40: =IFERROR(G40/C40,0) -> 4285.1555 | I40: =IFERROR(SUMIF(Creatives!$C$2:$C$264,B40,Creatives!$J$2:$J$264)/SUMIF(Creatives!$C$2:$C$264,B40,Creatives!$I$2:$I$264),0) -> 0.0095550057 | J40: =IFERROR(SUMIF(Creatives!$C$2:$C$264,B40,Creatives!$K$2:$K$264)/SUMIF(Creatives!$C$2:$C$264,B40,Creatives!$I$2:$I$264),0) -> 0.22475265 | K40: =IFERROR(G40/SUMIF(Creatives!$C$2:$C$264,B40,Creatives!$I$2:$I$264)*1000,0) -> 468.89 | L40: =SUMIF(Creatives!$C$2:$C$264,B40,Creatives!$O$2:$O$264) -> 61 | M40: =IFERROR(G40/L40,0) -> 2177.702 | N40: =SUMIF(Creatives!$C$2:$C$264,B40,Creatives!$U$2:$U$264) -> 768928.99
B41: 2026-09 | C41: =COUNTIF(Creatives!$C$2:$C$264,B41) -> 31 | D41: =COUNTIFS(Creatives!$C$2:$C$264,B41,Creatives!$Q$2:$Q$264,"Yes") -> 7 | E41: =IFERROR(D41/C41,0) -> 0.22580645 | F41: =IFERROR(AVERAGEIFS(Creatives!$S$2:$S$264,Creatives!$C$2:$C$264,B41,Creatives!$Q$2:$Q$264,"Yes"),0) -> 8.8571429 | G41: =SUMIF(Creatives!$C$2:$C$264,B41,Creatives!$H$2:$H$264) -> 143533.55 | H41: =IFERROR(G41/C41,0) -> 4630.1145 | I41: =IFERROR(SUMIF(Creatives!$C$2:$C$264,B41,Creatives!$J$2:$J$264)/SUMIF(Creatives!$C$2:$C$264,B41,Creatives!$I$2:$I$264),0) -> 0.009278315 | J41: =IFERROR(SUMIF(Creatives!$C$2:$C$264,B41,Creatives!$K$2:$K$264)/SUMIF(Creatives!$C$2:$C$264,B41,Creatives!$I$2:$I$264),0) -> 0.22044525 | K41: =IFERROR(G41/SUMIF(Creatives!$C$2:$C$264,B41,Creatives!$I$2:$I$264)*1000,0) -> 550.0824 | L41: =SUMIF(Creatives!$C$2:$C$264,B41,Creatives!$O$2:$O$264) -> 41 | M41: =IFERROR(G41/L41,0) -> 3500.8183 | N41: =SUMIF(Creatives!$C$2:$C$264,B41,Creatives!$U$2:$U$264) -> 567548.31
B42: 2026-10 | C42: =COUNTIF(Creatives!$C$2:$C$264,B42) -> 35 | D42: =COUNTIFS(Creatives!$C$2:$C$264,B42,Creatives!$Q$2:$Q$264,"Yes") -> 2 | E42: =IFERROR(D42/C42,0) -> 0.057142857 | F42: =IFERROR(AVERAGEIFS(Creatives!$S$2:$S$264,Creatives!$C$2:$C$264,B42,Creatives!$Q$2:$Q$264,"Yes"),0) -> 8.5 | G42: =SUMIF(Creatives!$C$2:$C$264,B42,Creatives!$H$2:$H$264) -> 184913.49 | H42: =IFERROR(G42/C42,0) -> 5283.2426 | I42: =IFERROR(SUMIF(Creatives!$C$2:$C$264,B42,Creatives!$J$2:$J$264)/SUMIF(Creatives!$C$2:$C$264,B42,Creatives!$I$2:$I$264),0) -> 0.008517639 | J42: =IFERROR(SUMIF(Creatives!$C$2:$C$264,B42,Creatives!$K$2:$K$264)/SUMIF(Creatives!$C$2:$C$264,B42,Creatives!$I$2:$I$264),0) -> 0.2258705 | K42: =IFERROR(G42/SUMIF(Creatives!$C$2:$C$264,B42,Creatives!$I$2:$I$264)*1000,0) -> 529.06495 | L42: =SUMIF(Creatives!$C$2:$C$264,B42,Creatives!$O$2:$O$264) -> 53 | M42: =IFERROR(G42/L42,0) -> 3488.9338 | N42: =SUMIF(Creatives!$C$2:$C$264,B42,Creatives!$U$2:$U$264) -> 115466.84
B43: Total | C43: =SUM(C33:C42) -> 263 | D43: =SUM(D33:D42) -> 59 | E43: =IFERROR(D43/C43,0) -> 0.2243346 | F43: =C17 -> 13.20339 | G43: =SUM(G33:G42) -> 2097022.3 | H43: =IFERROR(G43/C43,0) -> 7973.4687 | I43: =IFERROR(SUM(Creatives!$J$2:$J$264)/SUM(Creatives!$I$2:$I$264),0) -> 0.0039113224 | J43: =IFERROR(SUM(Creatives!$K$2:$K$264)/SUM(Creatives!$I$2:$I$264),0) -> 0.084770552 | K43: =IFERROR(G43/SUM(Creatives!$I$2:$I$264)*1000,0) -> 29.050234 | L43: =SUM(L33:L42) -> 510 | M43: =IFERROR(G43/L43,0) -> 4111.8084 | N43: =SUM(N33:N42) -> 7316800.8
B45: By testing campaign
...

Sheet Creatives
A1: Content (ad name at launch) | B1: Testing launch date | C1: Launch month | D1: Testing campaign | E1: Testing ad set | F1: Last spend in testing | G1: Age (days, as of data date) | H1: Testing spend | I1: Testing impressions | J1: Testing link clicks | K1: Testing video views (hook) | L1: Testing CTR | M1: Testing hook rate | N1: Testing CPM | O1: Testing appointments (Meta) | P1: Cost per appointment | Q1: Moved to scaling? | R1: Scaling start date | S1: Days to scale | T1: Scaling campaign(s) | U1: Scaling spend | V1: Scaling impressions | W1: Scaling link clicks | X1: Scaling video views (hook) | Y1: Scaling CTR | Z1: Scaling hook rate | AA1: Scaling appointments (Meta)
A2: MOF_Test_At Rings & I Our Rings Take 14 Days_170226 | B2: 46070 | C2: =TEXT(B2,"yyyy-mm") -> 2026-02 | D2: TOF CBO _Mumbai_CNV_060326 | E2: Testing_ad_set_241025 | F2: 46119 | G2: =Summary!$C$5-B2 -> 250 | H2: 84491.93 | I2: 616630 | J2: 2699 | K2: 63620 | L2: =IFERROR(J2/I2,"-") -> 0.004377017 | M2: =IFERROR(K2/I2,"-") -> 0.1031737 | N2: =IFERROR(H2/I2*1000,"-") -> 137.02209 | O2: 17 | P2: =IFERROR(H2/O2,"-") -> 4970.1135 | Q2: No | S2: =IF(Q2="Yes",R2-B2,"") | U2: 0 | V2: 0 | W2: 0 | X2: 0 | Y2: =IF(Q2="Yes",IFERROR(W2/V2,"-"),"") | Z2: =IF(Q2="Yes",IFERROR(X2/V2,"-"),"") | AA2: 0
A3: MOF_Test_Build Your Engagement Rings_170226 | B3: 46070 | C3: =TEXT(B3,"yyyy-mm") -> 2026-02 | D3: TOF CBO _Mumbai_CNV_060326 | E3: Testing_ad_set_241025 | F3: 46077 | G3: =Summary!$C$5-B3 -> 250 | H3: 8897.63 | I3: 67376 | J3: 169 | K3: 19776 | L3: =IFERROR(J3/I3,"-") -> 0.0025083116 | M3: =IFERROR(K3/I3,"-") -> 0.29351698 | N3: =IFERROR(H3/I3*1000,"-") -> 132.05934 | O3: 0 | P3: =IFERROR(H3/O3,"-") -> - | Q3: No | S3: =IF(Q3="Yes",R3-B3,"") | U3: 0 | V3: 0 | W3: 0 | X3: 0 | Y3: =IF(Q3="Yes",IFERROR(W3/V3,"-"),"") | Z3: =IF(Q3="Yes",IFERROR(X3/V3,"-"),"") | AA3: 0
A4: MOF_Test_Engrave_170226 | B4: 46070 | C4: =TEXT(B4,"yyyy-mm") -> 2026-02 | D4: TOF CBO _Mumbai_CNV_060326 | E4: Testing_ad_set_241025 | F4: 46077 | G4: =Summary!$C$5-B4 -> 250 | H4: 7057.41 | I4: 55349 | J4: 161 | K4: 15688 | L4: =IFERROR(J4/I4,"-") -> 0.002908815 | M4: =IFERROR(K4/I4,"-") -> 0.28343782 | N4: =IFERROR(H4/I4*1000,"-") -> 127.50745 | O4: 0 | P4: =IFERROR(H4/O4,"-") -> - | Q4: No | S4: =IF(Q4="Yes",R4-B4,"") | U4: 0 | V4: 0 | W4: 0 | X4: 0 | Y4: =IF(Q4="Yes",IFERROR(W4/V4,"-"),"") | Z4: =IF(Q4="Yes",IFERROR(X4/V4,"-"),"") | AA4: 0
A5: Test_Rings and I is not a jewellery store_170226 | B5: 46070 | C5: =TEXT(B5,"yyyy-mm") -> 2026-02 | D5: TOF CBO _Mumbai_CNV_060326 | E5: Testing_ad_set_241025 | F5: 46087 | G5: =Summary!$C$5-B5 -> 250 | H5: 7403.22 | I5: 24799 | J5: 98 | K5: 2326 | L5: =IFERROR(J5/I5,"-") -> 0.0039517722 | M5: =IFERROR(K5/I5,"-") -> 0.093794105 | N5: =IFERROR(H5/I5*1000,"-") -> 298.52897 | O5: 1 | P5: =IFERROR(H5/O5,"-") -> 7403.22 | Q5: No | S5: =IF(Q5="Yes",R5-B5,"") | U5: 0 | V5: 0 | W5: 0 | X5: 0 | Y5: =IF(Q5="Yes",IFERROR(W5/V5,"-"),"") | Z5: =IF(Q5="Yes",IFERROR(X5/V5,"-"),"") | AA5: 0
A6: Test_The Only Engagement Ring Studio_24022026 | B6: 46077 | C6: =TEXT(B6,"yyyy-mm") -> 2026-02 | D6: TOF CBO _Mumbai_CNV_060326 | E6: Testing_ad_set_241025 | F6: 46107 | G6: =Summary!$C$5-B6 -> 243 | H6: 24506.44 | I6: 218309 | J6: 1483 | K6: 8474 | L6: =IFERROR(J6/I6,"-") -> 0.0067931235 | M6: =IFERROR(K6/I6,"-") -> 0.03881654 | N6: =IFERROR(H6/I6*1000,"-") -> 112.25575 | O6: 2 | P6: =IFERROR(H6/O6,"-") -> 12253.22 | Q6: No | S6: =IF(Q6="Yes",R6-B6,"") | U6: 0 | V6: 0 | W6: 0 | X6: 0 | Y6: =IF(Q6="Yes",IFERROR(W6/V6,"-"),"") | Z6: =IF(Q6="Yes",IFERROR(X6/V6,"-"),"") | AA6: 0
A7: Test_Build Your Own Ring_24022026 | B7: 46078 | C7: =TEXT(B7,"yyyy-mm") -> 2026-02 | D7: TOF CBO _Mumbai_CNV_060326 | E7: Testing_ad_set_241025 | F7: 46099 | G7: =Summary!$C$5-B7 -> 242 | H7: 39811.39 | I7: 309580 | J7: 1481 | K7: 50673 | L7: =IFERROR(J7/I7,"-") -> 0.0047839008 | M7: =IFERROR(K7/I7,"-") -> 0.16368305 | N7: =IFERROR(H7/I7*1000,"-") -> 128.59807 | O7: 8 | P7: =IFERROR(H7/O7,"-") -> 4976.4237 | Q7: No | S7: =IF(Q7="Yes",R7-B7,"") | U7: 0 | V7: 0 | W7: 0 | X7: 0 | Y7: =IF(Q7="Yes",IFERROR(W7/V7,"-"),"") | Z7: =IF(Q7="Yes",IFERROR(X7/V7,"-"),"") | AA7: 0
A8: Test_Building a Ring_24022026 | B8: 46078 | C8: =TEXT(B8,"yyyy-mm") -> 2026-02 | D8: TOF CBO _Mumbai_CNV_060326 | E8: Testing_ad_set_241025 | F8: 46105 | G8: =Summary!$C$5-B8 -> 242 | H8: 3584.68 | I8: 16741 | J8: 29 | K8: 1869 | L8: =IFERROR(J8/I8,"-") -> 0.0017322741 | M8: =IFERROR(K8/I8,"-") -> 0.11164208 | N8: =IFERROR(H8/I8*1000,"-") -> 214.1258 | O8: 1 | P8: =IFERROR(H8/O8,"-") -> 3584.68 | Q8: No | S8: =IF(Q8="Yes",R8-B8,"") | U8: 0 | V8: 0 | W8: 0 | X8: 0 | Y8: =IF(Q8="Yes",IFERROR(W8/V8,"-"),"") | Z8: =IF(Q8="Yes",IFERROR(X8/V8,"-"),"") | AA8: 0
A9: Test_1000+ Engagement Rings For Men_24022026 | B9: 46079 | C9: =TEXT(B9,"yyyy-mm") -> 2026-02 | D9: TOF CBO _Mumbai_CNV_060326 | E9: Testing_ad_set_241025 | F9: 46089 | G9: =Summary!$C$5-B9 -> 241 | H9: 15318.49 | I9: 88249 | J9: 402 | K9: 16418 | L9: =IFERROR(J9/I9,"-") -> 0.0045552924 | M9: =IFERROR(K9/I9,"-") -> 0.18604177 | N9: =IFERROR(H9/I9*1000,"-") -> 173.58259 | O9: 4 | P9: =IFERROR(H9/O9,"-") -> 3829.6225 | Q9: No | S9: =IF(Q9="Yes",R9-B9,"") | U9: 0 | V9: 0 | W9: 0 | X9: 0 | Y9: =IF(Q9="Yes",IFERROR(W9/V9,"-"),"") | Z9: =IF(Q9="Yes",IFERROR(X9/V9,"-"),"") | AA9: 0
A10: MOF_Engrave 1_07032026 | B10: 46088 | C10: =TEXT(B10,"yyyy-mm") -> 2026-03 | D10: Testing _Mumbai_ABO_ Campaign | E10: Test_2_MOF_060326 | F10: 46099 | G10: =Summary!$C$5-B10 -> 232 | H10: 11805.55 | I10: 33102 | J10: 301 | K10: 9752 | L10: =IFERROR(J10/I10,"-") -> 0.0090931062 | M10: =IFERROR(K10/I10,"-") -> 0.29460456 | N10: =IFERROR(H10/I10*1000,"-") -> 356.64159 | O10: 3 | P10: =IFERROR(H10/O10,"-") -> 3935.1833 | Q10: Yes | R10: 46101 | S10: =IF(Q10="Yes",R10-B10,"") -> 13 | T10: MOF_ABO_Mumbai_CNV_211224 | U10: 64633.27 | V10: 326836 | W10: 1984 | X10: 71191.09 | Y10: =IF(Q10="Yes",IFERROR(W10/V10,"-"),"") -> 0.0060703227 | Z10: =IF(Q10="Yes",IFERROR(X10/V10,"-"),"") -> 0.217819 | AA10: 16
A11: MOF_Gold Tones_07032026 | B11: 46088 | C11: =TEXT(B11,"yyyy-mm") -> 2026-03 | D11: Testing _Mumbai_ABO_ Campaign | E11: Test_2_MOF_060326 | F11: 46206 | G11: =Summary!$C$5-B11 -> 232 | H11: 12704.62 | I11: 1024986 | J11: 597 | K11: 84292.53 | L11: =IFERROR(J11/I11,"-") -> 0.00058244698 | M11: =IFERROR(K11/I11,"-") -> 0.082237738 | N11: =IFERROR(H11/I11*1000,"-") -> 12.394921 | O11: 3 | P11: =IFERROR(H11/O11,"-") -> 4234.8733 | Q11: Yes | R11: 46099 | S11: =IF(Q11="Yes",R11-B11,"") -> 11 | T11: MOF_ABO_Mumbai_CNV_211224 | U11: 28421.67 | V11: 146160 | W11: 990 | X11: 36244.35 | Y11: =IF(Q11="Yes",IFERROR(W11/V11,"-"),"") -> 0.006773399 | Z11: =IF(Q11="Yes",IFERROR(X11/V11,"-"),"") -> 0.24797722 | AA11: 7
A12: TOF_BYOR_1_0732026 | B12: 46088 | C12: =TEXT(B12,"yyyy-mm") -> 2026-03 | D12: Testing _Mumbai_ABO_ Campaign | E12: Test_1_TOF_060326 | F12: 46118 | G12: =Summary!$C$5-B12 -> 232 | H12: 4681.74 | I12: 31841 | J12: 276 | K12: 3529 | L12: =IFERROR(J12/I12,"-") -> 0.0086680695 | M12: =IFERROR(K12/I12,"-") -> 0.11083195 | N12: =IFERROR(H12/I12*1000,"-") -> 147.03495 | O12: 4 | P12: =IFERROR(H12/O12,"-") -> 1170.435 | Q12: No | S12: =IF(Q12="Yes",R12-B12,"") | U12: 0 | V12: 0 | W12: 0 | X12: 0 | Y12: =IF(Q12="Yes",IFERROR(W12/V12,"-"),"") | Z12: =IF(Q12="Yes",IFERROR(X12/V12,"-"),"") | AA12: 0
A13: TOF_BYOR_2__0732026 | B13: 46088 | C13: =TEXT(B13,"yyyy-mm") -> 2026-03 | D13: Testing _Mumbai_ABO_ Campaign | E13: Test_1_TOF_060326 | F13: 46104 | G13: =Summary!$C$5-B13 -> 232 | H13: 23470.05 | I13: 197832 | J13: 1415 | K13: 49077 | L13: =IFERROR(J13/I13,"-") -> 0.0071525335 | M13: =IFERROR(K13/I13,"-") -> 0.24807412 | N13: =IFERROR(H13/I13*1000,"-") -> 118.63627 | O13: 8 | P13: =IFERROR(H13/O13,"-") -> 2933.7562 | Q13: No | S13: =IF(Q13="Yes",R13-B13,"") | U13: 0 | V13: 0 | W13: 0 | X13: 0 | Y13: =IF(Q13="Yes",IFERROR(W13/V13,"-"),"") | Z13: =IF(Q13="Yes",IFERROR(X13/V13,"-"),"") | AA13: 0
A14: Build Your Own Ring_09032026 | B14: 46090 | C14: =TEXT(B14,"yyyy-mm") -> 2026-03 | D14: Testing _Mumbai_ABO_ Campaign | E14: Test_1_TOF_060326 | F14: 46118 | G14: =Summary!$C$5-B14 -> 230 | H14: 1335.12 | I14: 3793 | J14: 9 | K14: 348 | L14: =IFERROR(J14/I14,"-") -> 0.002372792 | M14: =IFERROR(K14/I14,"-") -> 0.091747957 | N14: =IFERROR(H14/I14*1000,"-") -> 351.99578 | O14: 0 | P14: =IFERROR(H14/O14,"-") -> - | Q14: No | S14: =IF(Q14="Yes",R14-B14,"") | U14: 0 | V14: 0 | W14: 0 | X14: 0 | Y14: =IF(Q14="Yes",IFERROR(W14/V14,"-"),"") | Z14: =IF(Q14="Yes",IFERROR(X14/V14,"-"),"") | AA14: 0
A15: Reason Why Mumbai Couple Buy Engagement Ring Here_09032026 | B15: 46090 | C15: =TEXT(B15,"yyyy-mm") -> 2026-03 | D15: Testing _Mumbai_ABO_ Campaign | E15: Test_1_TOF_060326 | F15: 46104 | G15: =Summary!$C$5-B15 -> 230 | H15: 5632.91 | I15: 44139 | J15: 140 | K15: 10046 | L15: =IFERROR(J15/I15,"-") -> 0.0031717982 | M15: =IFERROR(K15/I15,"-") -> 0.22759918 | N15: =IFERROR(H15/I15*1000,"-") -> 127.61753 | O15: 2 | P15: =IFERROR(H15/O15,"-") -> 2816.455 | Q15: No | S15: =IF(Q15="Yes",R15-B15,"") | U15: 0 | V15: 0 | W15: 0 | X15: 0 | Y15: =IF(Q15="Yes",IFERROR(W15/V15,"-"),"") | Z15: =IF(Q15="Yes",IFERROR(X15/V15,"-"),"") | AA15: 0
A16: Education_Ad_1032026 | B16: 46091 | C16: =TEXT(B16,"yyyy-mm") -> 2026-03 | D16: Testing _Mumbai_ABO_ Campaign | E16: Test_2_MOF_060326 | F16: 46107 | G16: =Summary!$C$5-B16 -> 229 | H16: 4312.71 | I16: 6697 | J16: 46 | K16: 735 | L16: =IFERROR(J16/I16,"-") -> 0.0068687472 | M16: =IFERROR(K16/I16,"-") -> 0.10975063 | N16: =IFERROR(H16/I16*1000,"-") -> 643.97641 | O16: 7 | P16: =IFERROR(H16/O16,"-") -> 616.10143 | Q16: Yes | R16: 46104 | S16: =IF(Q16="Yes",R16-B16,"") -> 13 | T16: MOF_ABO_Mumbai_CNV_211224 | U16: 35987.52 | V16: 95214 | W16: 390 | X16: 8973.49 | Y16: =IF(Q16="Yes",IFERROR(W16/V16,"-"),"") -> 0.0040960363 | Z16: =IF(Q16="Yes",IFERROR(X16/V16,"-"),"") -> 0.094245489 | AA16: 4
A17: If I were Finding My Own Engagement Ring_1032026 | B17: 46091 | C17: =TEXT(B17,"yyyy-mm") -> 2026-03 | D17: Testing _Mumbai_ABO_ Campaign | E17: Test_2_MOF_060326 | F17: 46097 | G17: =Summary!$C$5-B17 -> 229 | H17: 2095.02 | I17: 5054 | J17: 30 | K17: 916 | L17: =IFERROR(J17/I17,"-") -> 0.0059358924 | M17: =IFERROR(K17/I17,"-") -> 0.18124258 | N17: =IFERROR(H17/I17*1000,"-") -> 414.52711 | O17: 0 | P17: =IFERROR(H17/O17,"-") -> - | Q17: No | S17: =IF(Q17="Yes",R17-B17,"") | U17: 0 | V17: 0 | W17: 0 | X17: 0 | Y17: =IF(Q17="Yes",IFERROR(W17/V17,"-"),"") | Z17: =IF(Q17="Yes",IFERROR(X17/V17,"-"),"") | AA17: 0
A18: Testimonial 4_100326 | B18: 46091 | C18: =TEXT(B18,"yyyy-mm") -> 2026-03 | D18: Testing _Mumbai_ABO_ Campaign | E18: Test_2_MOF_060326 | F18: 46107 | G18: =Summary!$C$5-B18 -> 229 | H18: 8516.26 | I18: 16240 | J18: 104 | K18: 3357 | L18: =IFERROR(J18/I18,"-") -> 0.0064039409 | M18: =IFERROR(K18/I18,"-") -> 0.20671182 | N18: =IFERROR(H18/I18*1000,"-") -> 524.40025 | O18: 6 | P18: =IFERROR(H18/O18,"-") -> 1419.3767 | Q18: Yes | R18: 46104 | S18: =IF(Q18="Yes",R18-B18,"") -> 13 | T18: MOF_ABO_Mumbai_CNV_211224 | U18: 39666.48 | V18: 219864 | W18: 2022 | X18: 33184.72 | Y18: =IF(Q18="Yes",IFERROR(W18/V18,"-"),"") -> 0.0091965943 | Z18: =IF(Q18="Yes",IFERROR(X18/V18,"-"),"") -> 0.15093294 | AA18: 21
A19: Unboxing_10032026 | B19: 46091 | C19: =TEXT(B19,"yyyy-mm") -> 2026-03 | D19: Testing _Mumbai_ABO_ Campaign | E19: Test_2_MOF_060326 | F19: 46104 | G19: =Summary!$C$5-B19 -> 229 | H19: 7231.83 | I19: 14670 | J19: 67 | K19: 3264 | L19: =IFERROR(J19/I19,"-") -> 0.0045671438 | M19: =IFERROR(K19/I19,"-") -> 0.22249489 | N19: =IFERROR(H19/I19*1000,"-") -> 492.96728 | O19: 1 | P19: =IFERROR(H19/O19,"-") -> 7231.83 | Q19: No | S19: =IF(Q19="Yes",R19-B19,"") | U19: 0 | V19: 0 | W19: 0 | X19: 0 | Y19: =IF(Q19="Yes",IFERROR(W19/V19,"-"),"") | Z19: =IF(Q19="Yes",IFERROR(X19/V19,"-"),"") | AA19: 0
A20: When Celebrities Dont Buy Ready-Made Engagement Ring_090326 | B20: 46091 | C20: =TEXT(B20,"yyyy-mm") -> 2026-03 | D20: Testing _Mumbai_ABO_ Campaign | E20: Test_1_TOF_060326 | F20: 46104 | G20: =Summary!$C$5-B20 -> 229 | H20: 545.33 | I20: 2187 | J20: 14 | K20: 711 | L20: =IFERROR(J20/I20,"-") -> 0.0064014632 | M20: =IFERROR(K20/I20,"-") -> 0.32510288 | N20: =IFERROR(H20/I20*1000,"-") -> 249.35071 | O20: 0 | P20: =IFERROR(H20/O20,"-") -> - | Q20: Yes | R20: 46104 | S20: =IF(Q20="Yes",R20-B20,"") -> 13 | T20: TOF CBO _Mumbai_CNV_060326 | U20: 71941.33 | V20: 667037 | W20: 4972 | X20: 114276.9 | Y20: =IF(Q20="Yes",IFERROR(W20/V20,"-"),"") -> 0.0074538594 | Z20: =IF(Q20="Yes",IFERROR(X20/V20,"-"),"") -> 0.17132018 | AA20: 7
A21: You Notice the Rings Worn by Vijay & Rashmika Mandanna at their Wedding_090326 | B21: 46091 | C21: =TEXT(B21,"yyyy-mm") -> 2026-03 | D21: Testing _Mumbai_ABO_ Campaign | E21: Test_1_TOF_060326 | F21: 46233 | G21: =Summary!$C$5-B21 -> 229 | H21: 115732.09 | I21: 3872854 | J21: 211003 | K21: 1313202 | L21: =IFERROR(J21/I21,"-") -> 0.05448256 | M21: =IFERROR(K21/I21,"-") -> 0.33907861 | N21: =IFERROR(H21/I21*1000,"-") -> 29.882895 | O21: 0 | P21: =IFERROR(H21/O21,"-") -> - | Q21: Yes | R21: 46104 | S21: =IF(Q21="Yes",R21-B21,"") -> 13 | T21: TOF CBO _Mumbai_CNV_060326 | U21: 1072285.4 | V21: 18088242 | W21: 359792 | X21: 5726738.6 | Y21: =IF(Q21="Yes",IFERROR(W21/V21,"-"),"") -> 0.019890932 | Z21: =IF(Q21="Yes",IFERROR(X21/V21,"-"),"") -> 0.31660007 | AA21: 62
A22: TOF_#1A - How do you Know if the Shape is Right | B22: 46105 | C22: =TEXT(B22,"yyyy-mm") -> 2026-03 | D22: Testing _Mumbai_ABO_ Campaign | E22: Test_1_TOF_060326 | F22: 46119 | G22: =Summary!$C$5-B22 -> 215 | H22: 4959.16 | I22: 22283 | J22: 70 | K22: 3812 | L22: =IFERROR(J22/I22,"-") -> 0.0031414082 | M22: =IFERROR(K22/I22,"-") -> 0.17107212 | N22: =IFERROR(H22/I22*1000,"-") -> 222.55352 | O22: 4 | P22: =IFERROR(H22/O22,"-") -> 1239.79 | Q22: Yes | R22: 46118 | S22: =IF(Q22="Yes",R22-B22,"") -> 13 | T22: TOF CBO _Mumbai_CNV_060326 | U22: 86556.48 | V22: 520606 | W22: 1352 | X22: 59493.28 | Y22: =IF(Q22="Yes",IFERROR(W22/V22,"-"),"") -> 0.0025969735 | Z22: =IF(Q22="Yes",IFERROR(X22/V22,"-"),"") -> 0.11427698 | AA22: 3
A23: TOF_#2Here's the Difference Between | B23: 46105 | C23: =TEXT(B23,"yyyy-mm") -> 2026-03 | D23: Testing _Mumbai_ABO_ Campaign | E23: Test_1_TOF_060326 | F23: 46118 | G23: =Summary!$C$5-B23 -> 215 | H23: 4800.66 | I23: 16973 | J23: 105 | K23: 5669 | L23: =IFERROR(J23/I23,"-") -> 0.0061862959 | M23: =IFERROR(K23/I23,"-") -> 0.33400106 | N23: =IFERROR(H23/I23*1000,"-") -> 282.84098 | O23: 1 | P23: =IFERROR(H23/O23,"-") -> 4800.66 | Q23: No | S23: =IF(Q23="Yes",R23-B23,"") | U23: 0 | V23: 0 | W23: 0 | X23: 0 | Y23: =IF(Q23="Yes",IFERROR(W23/V23,"-"),"") | Z23: =IF(Q23="Yes",IFERROR(X23/V23,"-"),"") | AA23: 0
A24: TOF_#3What if you could Build your Engagement Ring | B24: 46105 | C24: =TEXT(B24,"yyyy-mm") -> 2026-03 | D24: Testing _Mumbai_ABO_ Campaign | E24: Test_1_TOF_060326 | F24: 46119 | G24: =Summary!$C$5-B24 -> 215 | H24: 7857.46 | I24: 33523 | J24: 81 | K24: 3994 | L24: =IFERROR(J24/I24,"-") -> 0.0024162515 | M24: =IFERROR(K24/I24,"-") -> 0.11914208 | N24: =IFERROR(H24/I24*1000,"-") -> 234.39012 | O24: 3 | P24: =IFERROR(H24/O24,"-") -> 2619.1533 | Q24: Yes | R24: 46119 | S24: =IF(Q24="Yes",R24-B24,"") -> 14 | T24: TOF CBO _Mumbai_CNV_060326 | U24: 237552.66 | V24: 1229269 | W24: 3128 | X24: 109630.41 | Y24: =IF(Q24="Yes",IFERROR(W24/V24,"-"),"") -> 0.0025446017 | Z24: =IF(Q24="Yes",IFERROR(X24/V24,"-"),"") -> 0.089183417 | AA24: 9
A25: TOF_Even Rashmika Got VIjay His Dream_240326 | B25: 46105 | C25: =TEXT(B25,"yyyy-mm") -> 2026-03 | D25: Testing _Mumbai_ABO_ Campaign | E25: Test_1_TOF_060326 | F25: 46119 | G25: =Summary!$C$5-B25 -> 215 | H25: 2753.72 | I25: 14142 | J25: 60 | K25: 4167 | L25: =IFERROR(J25/I25,"-") -> 0.0042426814 | M25: =IFERROR(K25/I25,"-") -> 0.29465422 | N25: =IFERROR(H25/I25*1000,"-") -> 194.71928 | O25: 0 | P25: =IFERROR(H25/O25,"-") -> - | Q25: Yes | R25: 46119 | S25: =IF(Q25="Yes",R25-B25,"") -> 14 | T25: TOF CBO _Mumbai_CNV_060326 | U25: 101064.15 | V25: 1816318 | W25: 6432 | X25: 414412.59 | Y25: =IF(Q25="Yes",IFERROR(W25/V25,"-"),"") -> 0.0035412301 | Z25: =IF(Q25="Yes",IFERROR(X25/V25,"-"),"") -> 0.22816081 | AA25: 7
A26: TOF_Test_Celebs who chose Couple Engagement Rings | B26: 46105 | C26: =TEXT(B26,"yyyy-mm") -> 2026-03 | D26: Testing _Mumbai_ABO_ Campaign | E26: Test_1_TOF_060326 | F26: 46206 | G26: =Summary!$C$5-B26 -> 215 | H26: 15963.05 | I26: 2426416 | J26: 1397 | K26: 289666.86 | L26: =IFERROR(J26/I26,"-") -> 0.00057574629 | M26: =IFERROR(K26/I26,"-") -> 0.11938054 | N26: =IFERROR(H26/I26*1000,"-") -> 6.5788595 | O26: 3 | P26: =IFERROR(H26/O26,"-") -> 5321.0167 | Q26: Yes | R26: 46112 | S26: =IF(Q26="Yes",R26-B26,"") -> 7 | T26: TOF CBO _Mumbai_CNV_060326 | U26: 548048.64 | V26: 5112283 | W26: 31252 | X26: 1370778.8 | Y26: =IF(Q26="Yes",IFERROR(W26/V26,"-"),"") -> 0.0061131201 | Z26: =IF(Q26="Yes",IFERROR(X26/V26,"-"),"") -> 0.26813437 | AA26: 23
A27: TOF_Women in Love Helping Men_06042026 | B27: 46105 | C27: =TEXT(B27,"yyyy-mm") -> 2026-03 | D27: Testing _Mumbai_ABO_ Campaign | E27: Test_1_TOF_060326 | F27: 46118 | G27: =Summary!$C$5-B27 -> 215 | H27: 2940.12 | I27: 16036 | J27: 31 | K27: 2606 | L27: =IFERROR(J27/I27,"-") -> 0.0019331504 | M27: =IFERROR(K27/I27,"-") -> 0.16250935 | N27: =IFERROR(H27/I27*1000,"-") -> 183.34497 | O27: 0 | P27: =IFERROR(H27/O27,"-") -> - | Q27: No | S27: =IF(Q27="Yes",R27-B27,"") | U27: 0 | V27: 0 | W27: 0 | X27: 0 | Y27: =IF(Q27="Yes",IFERROR(W27/V27,"-"),"") | Z27: =IF(Q27="Yes",IFERROR(X27/V27,"-"),"") | AA27: 0
A28: TOF#1B - This Might be the Smartest Way to Buy Engagement Rings | B28: 46106 | C28: =TEXT(B28,"yyyy-mm") -> 2026-03 | D28: Testing _Mumbai_ABO_ Campaign | E28: Test_1_TOF_060326 | F28: 46118 | G28: =Summary!$C$5-B28 -> 214 | H28: 2834.46 | I28: 10779 | J28: 37 | K28: 1934 | L28: =IFERROR(J28/I28,"-") -> 0.0034326004 | M28: =IFERROR(K28/I28,"-") -> 0.17942295 | N28: =IFERROR(H28/I28*1000,"-") -> 262.96131 | O28: 0 | P28: =IFERROR(H28/O28,"-") -> - | Q28: No | S28: =IF(Q28="Yes",R28-B28,"") | U28: 0 | V28: 0 | W28: 0 | X28: 0 | Y28: =IF(Q28="Yes",IFERROR(W28/V28,"-"),"") | Z28: =IF(Q28="Yes",IFERROR(X28/V28,"-"),"") | AA28: 0
A29: Founders Vid_3_13126 – Copy_Borvali5 | B29: 46113 | C29: =TEXT(B29,"yyyy-mm") -> 2026-04 | D29: Testing _Mumbai_ABO_ Campaign | E29: Test_Borivali Studio_310326 | F29: 46126 | G29: =Summary!$C$5-B29 -> 207 | H29: 16051.63 | I29: 57655 | J29: 286 | K29: 13757 | L29: =IFERROR(J29/I29,"-") -> 0.0049605411 | M29: =IFERROR(K29/I29,"-") -> 0.23860897 | N29: =IFERROR(H29/I29*1000,"-") -> 278.40829 | O29: 5 | P29: =IFERROR(H29/O29,"-") -> 3210.326 | Q29: No | S29: =IF(Q29="Yes",R29-B29,"") | U29: 0 | V29: 0 | W29: 0 | X29: 0 | Y29: =IF(Q29="Yes",IFERROR(W29/V29,"-"),"") | Z29: =IF(Q29="Yes",IFERROR(X29/V29,"-"),"") | AA29: 0
A30: Test_BYOR_Borivali_010426 | B30: 46113 | C30: =TEXT(B30,"yyyy-mm") -> 2026-04 | D30: Testing _Mumbai_ABO_ Campaign | E30: Test_Borivali Studio_310326 | F30: 46126 | G30: =Summary!$C$5-B30 -> 207 | H30: 7164.1 | I30: 37817 | J30: 272 | K30: 8627 | L30: =IFERROR(J30/I30,"-") -> 0.0071925325 | M30: =IFERROR(K30/I30,"-") -> 0.22812492 | N30: =IFERROR(H30/I30*1000,"-") -> 189.44126 | O30: 0 | P30: =IFERROR(H30/O30,"-") -> - | Q30: No | S30: =IF(Q30="Yes",R30-B30,"") | U30: 0 | V30: 0 | W30: 0 | X30: 0 | Y30: =IF(Q30="Yes",IFERROR(W30/V30,"-"),"") | Z30: =IF(Q30="Yes",IFERROR(X30/V30,"-"),"") | AA30: 0
A31: MOF_Gold Tones_06042026 | B31: 46118 | C31: =TEXT(B31,"yyyy-mm") -> 2026-04 | D31: Testing _Mumbai_ABO_ Campaign | E31: Test_2_MOF_060326 | F31: 46127 | G31: =Summary!$C$5-B31 -> 202 | H31: 10757.87 | I31: 24340 | J31: 347 | K31: 8307 | L31: =IFERROR(J31/I31,"-") -> 0.014256368 | M31: =IFERROR(K31/I31,"-") -> 0.34129006 | N31: =IFERROR(H31/I31*1000,"-") -> 441.98316 | O31: 3 | P31: =IFERROR(H31/O31,"-") -> 3585.9567 | Q31: Yes | R31: 46187 | S31: =IF(Q31="Yes",R31-B31,"") -> 69 | T31: MOF_ABO_Mumbai_CNV_211224 | U31: 38554.99 | V31: 201229 | W31: 2372 | X31: 40074.86 | Y31: =IF(Q31="Yes",IFERROR(W31/V31,"-"),"") -> 0.011787565 | Z31: =IF(Q31="Yes",IFERROR(X31/V31,"-"),"") -> 0.19915052 | AA31: 10
A32: MOF_Test_Appointment_06042026 | B32: 46118 | C32: =TEXT(B32,"yyyy-mm") -> 2026-04 | D32: Testing _Mumbai_ABO_ Campaign | E32: Test_2_MOF_060326 | F32: 46133 | G32: =Summary!$C$5-B32 -> 202 | H32: 4304.89 | I32: 10534 | J32: 46 | K32: 1002 | L32: =IFERROR(J32/I32,"-") -> 0.0043668122 | M32: =IFERROR(K32/I32,"-") -> 0.095120562 | N32: =IFERROR(H32/I32*1000,"-") -> 408.66622 | O32: 1 | P32: =IFERROR(H32/O32,"-") -> 4304.89 | Q32: Yes | R32: 46186 | S32: =IF(Q32="Yes",R32-B32,"") -> 68 | T32: MOF_ABO_Mumbai_CNV_211224 | U32: 11990.04 | V32: 34074 | W32: 117 | X32: 2825.38 | Y32: =IF(Q32="Yes",IFERROR(W32/V32,"-"),"") -> 0.0034337031 | Z32: =IF(Q32="Yes",IFERROR(X32/V32,"-"),"") -> 0.082918941 | AA32: 2
A33: MOF_Test_Diamond Certification_06042026 | B33: 46118 | C33: =TEXT(B33,"yyyy-mm") -> 2026-04 | D33: Testing _Mumbai_ABO_ Campaign | E33: Test_2_MOF_060326 | F33: 46133 | G33: =Summary!$C$5-B33 -> 202 | H33: 5488.73 | I33: 10128 | J33: 59 | K33: 1249 | L33: =IFERROR(J33/I33,"-") -> 0.0058254344 | M33: =IFERROR(K33/I33,"-") -> 0.12332148 | N33: =IFERROR(H33/I33*1000,"-") -> 541.93622 | O33: 3 | P33: =IFERROR(H33/O33,"-") -> 1829.5767 | Q33: Yes | R33: 46187 | S33: =IF(Q33="Yes",R33-B33,"") -> 69 | T33: MOF_ABO_Mumbai_CNV_211224 | U33: 15247.99 | V33: 73701 | W33: 228 | X33: 5859.33 | Y33: =IF(Q33="Yes",IFERROR(W33/V33,"-"),"") -> 0.0030935808 | Z33: =IF(Q33="Yes",IFERROR(X33/V33,"-"),"") -> 0.079501364 | AA33: 4
A34: MOF_Test_LabGRvsNat_06042026 | B34: 46118 | C34: =TEXT(B34,"yyyy-mm") -> 2026-04 | D34: Testing _Mumbai_ABO_ Campaign | E34: Test_2_MOF_060326 | F34: 46129 | G34: =Summary!$C$5-B34 -> 202 | H34: 6268.54 | I34: 15005 | J34: 106 | K34: 3092 | L34: =IFERROR(J34/I34,"-") -> 0.0070643119 | M34: =IFERROR(K34/I34,"-") -> 0.20606465 | N34: =IFERROR(H34/I34*1000,"-") -> 417.76341 | O34: 3 | P34: =IFERROR(H34/O34,"-") -> 2089.5133 | Q34: No | S34: =IF(Q34="Yes",R34-B34,"") | U34: 0 | V34: 0 | W34: 0 | X34: 0 | Y34: =IF(Q34="Yes",IFERROR(W34/V34,"-"),"") | Z34: =IF(Q34="Yes",IFERROR(X34/V34,"-"),"") | AA34: 0
A35: MOF_Test_No Fix Prices _06042026 | B35: 46118 | C35: =TEXT(B35,"yyyy-mm") -> 2026-04 | D35: Testing _Mumbai_ABO_ Campaign | E35: Test_2_MOF_060326 | F35: 46133 | G35: =Summary!$C$5-B35 -> 202 | H35: 1510.5 | I35: 2362 | J35: 12 | K35: 346 | L35: =IFERROR(J35/I35,"-") -> 0.0050804403 | M35: =IFERROR(K35/I35,"-") -> 0.14648603 | N35: =IFERROR(H35/I35*1000,"-") -> 639.50042 | O35: 1 | P35: =IFERROR(H35/O35,"-") -> 1510.5 | Q35: No | S35: =IF(Q35="Yes",R35-B35,"") | U35: 0 | V35: 0 | W35: 0 | X35: 0 | Y35: =IF(Q35="Yes",IFERROR(W35/V35,"-"),"") | Z35: =IF(Q35="Yes",IFERROR(X35/V35,"-"),"") | AA35: 0
A36: MOF_Test_Carousel 2 _06042026 | B36: 46119 | C36: =TEXT(B36,"yyyy-mm") -> 2026-04 | D36: Testing _Mumbai_ABO_ Campaign | E36: Test_2_MOF_060326 | F36: 46120 | G36: =Summary!$C$5-B36 -> 201 | H36: 1246.65 | I36: 2607 | J36: 20 | K36: 0 | L36: =IFERROR(J36/I36,"-") -> 0.0076716532 | M36: =IFERROR(K36/I36,"-") -> 0 | N36: =IFERROR(H36/I36*1000,"-") -> 478.19333 | O36: 2 | P36: =IFERROR(H36/O36,"-") -> 623.325 | Q36: No | S36: =IF(Q36="Yes",R36-B36,"") | U36: 0 | V36: 0 | W36: 0 | X36: 0 | Y36: =IF(Q36="Yes",IFERROR(W36/V36,"-"),"") | Z36: =IF(Q36="Yes",IFERROR(X36/V36,"-"),"") | AA36: 0
A37: TOF_Finishes_06042026 | B37: 46119 | C37: =TEXT(B37,"yyyy-mm") -> 2026-04 | D37: Testing _Mumbai_ABO_ Campaign | E37: Test_1_TOF_060326 | F37: 46159 | G37: =Summary!$C$5-B37 -> 201 | H37: 5589.59 | I37: 40534 | J37: 163 | K37: 4295 | L37: =IFERROR(J37/I37,"-") -> 0.0040213154 | M37: =IFERROR(K37/I37,"-") -> 0.10596043 | N37: =IFERROR(H37/I37*1000,"-") -> 137.8988 | O37: 1 | P37: =IFERROR(H37/O37,"-") -> 5589.59 | Q37: No | S37: =IF(Q37="Yes",R37-B37,"") | U37: 0 | V37: 0 | W37: 0 | X37: 0 | Y37: =IF(Q37="Yes",IFERROR(W37/V37,"-"),"") | Z37: =IF(Q37="Yes",IFERROR(X37/V37,"-"),"") | AA37: 0
A38: TOF_Hidden Details_0604206 | B38: 46119 | C38: =TEXT(B38,"yyyy-mm") -> 2026-04 | D38: Testing _Mumbai_ABO_ Campaign | E38: Test_1_TOF_060326 | F38: 46131 | G38: =Summary!$C$5-B38 -> 201 | H38: 1387.76 | I38: 4733 | J38: 10 | K38: 575 | L38: =IFERROR(J38/I38,"-") -> 0.0021128248 | M38: =IFERROR(K38/I38,"-") -> 0.12148743 | N38: =IFERROR(H38/I38*1000,"-") -> 293.20938 | O38: 0 | P38: =IFERROR(H38/O38,"-") -> - | Q38: No | S38: =IF(Q38="Yes",R38-B38,"") | U38: 0 | V38: 0 | W38: 0 | X38: 0 | Y38: =IF(Q38="Yes",IFERROR(W38/V38,"-"),"") | Z38: =IF(Q38="Yes",IFERROR(X38/V38,"-"),"") | AA38: 0
A39: TOF_If you dont Want_06042026 | B39: 46119 | C39: =TEXT(B39,"yyyy-mm") -> 2026-04 | D39: Testing _Mumbai_ABO_ Campaign | E39: Test_1_TOF_060326 | F39: 46125 | G39: =Summary!$C$5-B39 -> 201 | H39: 3212.33 | I39: 10966 | J39: 47 | K39: 1963 | L39: =IFERROR(J39/I39,"-") -> 0.0042859748 | M39: =IFERROR(K39/I39,"-") -> 0.17900784 | N39: =IFERROR(H39/I39*1000,"-") -> 292.93544 | O39: 0 | P39: =IFERROR(H39/O39,"-") -> - | Q39: No | S39: =IF(Q39="Yes",R39-B39,"") | U39: 0 | V39: 0 | W39: 0 | X39: 0 | Y39: =IF(Q39="Yes",IFERROR(W39/V39,"-"),"") | Z39: =IF(Q39="Yes",IFERROR(X39/V39,"-"),"") | AA39: 0
A40: TOF_Most Wanted Rings_06042026 | B40: 46119 | C40: =TEXT(B40,"yyyy-mm") -> 2026-04 | D40: Testing _Mumbai_ABO_ Campaign | E40: Test_1_TOF_060326 | F40: 46125 | G40: =Summary!$C$5-B40 -> 201 | H40: 9504.7 | I40: 40851 | J40: 217 | K40: 3955 | L40: =IFERROR(J40/I40,"-") -> 0.0053119875 | M40: =IFERROR(K40/I40,"-") -> 0.096815255 | N40: =IFERROR(H40/I40*1000,"-") -> 232.6675 | O40: 0 | P40: =IFERROR(H40/O40,"-") -> - | Q40: No | S40: =IF(Q40="Yes",R40-B40,"") | U40: 0 | V40: 0 | W40: 0 | X40: 0 | Y40: =IF(Q40="Yes",IFERROR(W40/V40,"-"),"") | Z40: =IF(Q40="Yes",IFERROR(X40/V40,"-"),"") | AA40: 0
...
